Workbook

Sheet Dashboard
A1: Big Books Company
B2: Income Statement | M2: Cash Flow Statement
C3: Actuals | F3: Forecast | N3: Actuals | Q3: Forecast
B4: ($ in Million Except Per Share Amounts) | C4: Historical 1 | D4: Historical 2 | E4: Historical 3 | F4: Forecast 1 | G4: Forecast 2 | H4: Forecast 3 | I4: Forecast 4 | J4: Forecast 5 | M4: ($ in Million Except Per Share Amounts) | N4: Historical 1 | O4: Historical 2 | P4: Historical 3 | Q4: Forecast 1 | R4: Forecast 2 | S4: Forecast 3 | T4: Forecast 4 | U4: Forecast 5
B5: Net Sales | C5: ='Income Statement'!C5 -> 2904.94 | D5: ='Income Statement'!D5 -> 3408 | E5: ='Income Statement'!E5 -> 3958.96 | F5: ='Income Statement'!F5 -> 4119.966 | G5: ='Income Statement'!G5 -> 4803.7718 | H5: ='Income Statement'!H5 -> 5602.8773 | I5: ='Income Statement'!I5 -> 6536.9387 | J5: ='Income Statement'!J5 -> 7628.9884 | M5: Operating Activities
B6: Cost of Sales | C6: ='Income Statement'!C6 -> 1494.8366 | D6: ='Income Statement'!D6 -> 1866.1246 | E6: ='Income Statement'!E6 -> 2309.7272 | F6: ='Income Statement'!F6 -> 2502.2446 | G6: ='Income Statement'!G6 -> 2916.6145 | H6: ='Income Statement'!H6 -> 3400.774 | I6: ='Income Statement'!I6 -> 3966.6171 | J6: ='Income Statement'!J6 -> 4628.0813 | M6: Net Income | O6: ='Cash Flow Statement'!D6 -> 754.10834 | P6: ='Cash Flow Statement'!E6 -> 740.30492 | Q6: ='Cash Flow Statement'!F6 -> 695.99587 | R6: ='Cash Flow Statement'!G6 -> 829.82064 | S6: ='Cash Flow Statement'!H6 -> 988.81888 | T6: ='Cash Flow Statement'!I6 -> 1173.3315 | U6: ='Cash Flow Statement'!J6 -> 1387.8812
B7: Gross Profit | C7: ='Income Statement'!C7 -> 1410.1034 | D7: ='Income Statement'!D7 -> 1541.8754 | E7: ='Income Statement'!E7 -> 1649.2328 | F7: ='Income Statement'!F7 -> 1617.7214 | G7: ='Income Statement'!G7 -> 1887.1573 | H7: ='Income Statement'!H7 -> 2202.1033 | I7: ='Income Statement'!I7 -> 2570.3216 | J7: ='Income Statement'!J7 -> 3000.9071 | M7: Depreciation | O7: ='Cash Flow Statement'!D7 -> 123.1 | P7: ='Cash Flow Statement'!E7 -> 140 | Q7: ='Cash Flow Statement'!F7 -> 151.53313 | R7: ='Cash Flow Statement'!G7 -> 179.55514 | S7: ='Cash Flow Statement'!H7 -> 212.23859 | T7: ='Cash Flow Statement'!I7 -> 250.37073 | U7: ='Cash Flow Statement'!J7 -> 294.87316
M8: Amortization | O8: ='Cash Flow Statement'!D8 -> 10.666 | P8: ='Cash Flow Statement'!E8 -> 13.035 | Q8: ='Cash Flow Statement'!F8 -> 13.295973 | R8: ='Cash Flow Statement'!G8 -> 17.13899 | S8: ='Cash Flow Statement'!H8 -> 21.621292 | T8: ='Cash Flow Statement'!I8 -> 26.850843 | U8: ='Cash Flow Statement'!J8 -> 32.954034
B9: Selling, General & Admin Costs | C9: ='Income Statement'!C9 -> 305.14255 | D9: ='Income Statement'!D9 -> 388.2872 | E9: ='Income Statement'!E9 -> 448.0675 | F9: ='Income Statement'!F9 -> 463.83868 | G9: ='Income Statement'!G9 -> 540.94103 | H9: ='Income Statement'!H9 -> 631.05976 | I9: ='Income Statement'!I9 -> 736.41607 | J9: ='Income Statement'!J9 -> 859.61298 | M9: Change in Working Capital | O9: ='Cash Flow Statement'!D9 -> 0 | P9: ='Cash Flow Statement'!E9 -> 0 | Q9: ='Cash Flow Statement'!F9 -> 0 | R9: ='Cash Flow Statement'!G9 -> 0 | S9: ='Cash Flow Statement'!H9 -> 0 | T9: ='Cash Flow Statement'!I9 -> 0 | U9: ='Cash Flow Statement'!J9 -> 0
B10: EBITDA | C10: ='Income Statement'!C10 -> 1104.9608 | D10: ='Income Statement'!D10 -> 1153.5882 | E10: ='Income Statement'!E10 -> 1201.1653 | F10: ='Income Statement'!F10 -> 1153.8827 | G10: ='Income Statement'!G10 -> 1346.2162 | H10: ='Income Statement'!H10 -> 1571.0435 | I10: ='Income Statement'!I10 -> 1833.9055 | J10: ='Income Statement'!J10 -> 2141.2941 | M10: Change in Assets & Liabilities (if any) | O10: ='Cash Flow Statement'!D16 -> -14 | P10: ='Cash Flow Statement'!E16 -> 36 | Q10: ='Cash Flow Statement'!F16 -> 0 | R10: ='Cash Flow Statement'!G16 -> 0 | S10: ='Cash Flow Statement'!H16 -> 0 | T10: ='Cash Flow Statement'!I16 -> 0 | U10: ='Cash Flow Statement'!J16 -> 0
M11: Cash Flow from Operating Activities | O11: ='Cash Flow Statement'!D17 -> 834.57434 | P11: ='Cash Flow Statement'!E17 -> 987.83992 | Q11: ='Cash Flow Statement'!F17 -> 891.97354 | R11: ='Cash Flow Statement'!G17 -> 964.77779 | S11: ='Cash Flow Statement'!H17 -> 1150.5262 | T11: ='Cash Flow Statement'!I17 -> 1366.2089 | U11: ='Cash Flow Statement'!J17 -> 1617.0918
B12: Depreciation | C12: ='Income Statement'!C12 -> 101.9 | D12: ='Income Statement'!D12 -> 123.1 | E12: ='Income Statement'!E12 -> 140 | F12: ='Income Statement'!F12 -> 151.53313 | G12: ='Income Statement'!G12 -> 179.55514 | H12: ='Income Statement'!H12 -> 212.23859 | I12: ='Income Statement'!I12 -> 250.37073 | J12: ='Income Statement'!J12 -> 294.87316 | O12: ='Cash Flow Statement'!D18 -> 0 | P12: ='Cash Flow Statement'!E18 -> 0 | Q12: ='Cash Flow Statement'!F18 -> 0 | R12: ='Cash Flow Statement'!G18 -> 0 | S12: ='Cash Flow Statement'!H18 -> 0 | T12: ='Cash Flow Statement'!I18 -> 0 | U12: ='Cash Flow Statement'!J18 -> 0
B13: Amortization | C13: ='Income Statement'!C13 -> 9.367 | D13: ='Income Statement'!D13 -> 10.666 | E13: ='Income Statement'!E13 -> 13.035 | F13: ='Income Statement'!F13 -> 13.295973 | G13: ='Income Statement'!G13 -> 17.13899 | H13: ='Income Statement'!H13 -> 21.621292 | I13: ='Income Statement'!I13 -> 26.850843 | J13: ='Income Statement'!J13 -> 32.954034 | M13: Investment Activities | O13: ='Cash Flow Statement'!D19 -> 0 | P13: ='Cash Flow Statement'!E19 -> 0 | Q13: ='Cash Flow Statement'!F19 -> 0 | R13: ='Cash Flow Statement'!G19 -> 0 | S13: ='Cash Flow Statement'!H19 -> 0 | T13: ='Cash Flow Statement'!I19 -> 0 | U13: ='Cash Flow Statement'!J19 -> 0
B14: EBIT | C14: ='Income Statement'!C14 -> 993.69382 | D14: ='Income Statement'!D14 -> 1019.8222 | E14: ='Income Statement'!E14 -> 1048.1303 | F14: ='Income Statement'!F14 -> 989.05358 | G14: ='Income Statement'!G14 -> 1149.5221 | H14: ='Income Statement'!H14 -> 1337.1836 | I14: ='Income Statement'!I14 -> 1556.684 | J14: ='Income Statement'!J14 -> 1813.4669 | M14: Purchase of Marketable Securities | O14: ='Cash Flow Statement'!D20 -> -10 | P14: ='Cash Flow Statement'!E20 -> -10 | Q14: ='Cash Flow Statement'!F20 -> -10 | R14: ='Cash Flow Statement'!G20 -> -10 | S14: ='Cash Flow Statement'!H20 -> -10 | T14: ='Cash Flow Statement'!I20 -> -10 | U14: ='Cash Flow Statement'!J20 -> -10
M15: Purchase of Long Term Securities | O15: ='Cash Flow Statement'!D21 -> -20 | P15: ='Cash Flow Statement'!E21 -> -20 | Q15: ='Cash Flow Statement'!F21 -> -20 | R15: ='Cash Flow Statement'!G21 -> -20 | S15: ='Cash Flow Statement'!H21 -> -20 | T15: ='Cash Flow Statement'!I21 -> -20 | U15: ='Cash Flow Statement'!J21 -> -20
B16: Interest Expense | C16: ='Income Statement'!C16 -> 44.10772 | D16: ='Income Statement'!D16 -> 60.11464 | E16: ='Income Statement'!E16 -> 63.765 | F16: ='Income Statement'!F16 -> 73.105859 | G16: ='Income Statement'!G16 -> 62.785391 | H16: ='Income Statement'!H16 -> 52.279533 | I16: ='Income Statement'!I16 -> 45.45 | J16: ='Income Statement'!J16 -> 43.2 | M16: Capital Expenditures | O16: ='Cash Flow Statement'!D22 -> -145 | P16: ='Cash Flow Statement'!E22 -> -250 | Q16: ='Cash Flow Statement'!F22 -> -288.39762 | R16: ='Cash Flow Statement'!G22 -> -336.26403 | S16: ='Cash Flow Statement'!H22 -> -392.20141 | T16: ='Cash Flow Statement'!I22 -> -457.58571 | U16: ='Cash Flow Statement'!J22 -> -534.02919
B17: Interest Income | C17: ='Income Statement'!C17 -> 0 | D17: ='Income Statement'!D17 -> 9.4007832 | E17: ='Income Statement'!E17 -> 10.939602 | F17: ='Income Statement'!F17 -> 11.002482 | G17: ='Income Statement'!G17 -> 11.176884 | H17: ='Income Statement'!H17 -> 13.793676 | I17: ='Income Statement'!I17 -> 22.634329 | J17: ='Income Statement'!J17 -> 36.809235 | M17: Additions to Intangibles | O17: ='Cash Flow Statement'!D23 -> -26.466 | P17: ='Cash Flow Statement'!E23 -> -30.735 | Q17: ='Cash Flow Statement'!F23 -> -32.959728 | R17: ='Cash Flow Statement'!G23 -> -38.430174 | S17: ='Cash Flow Statement'!H23 -> -44.823018 | T17: ='Cash Flow Statement'!I23 -> -52.295509 | U17: ='Cash Flow Statement'!J23 -> -61.031907
B18: Pretax Income | C18: ='Income Statement'!C18 -> 949.5861 | D18: ='Income Statement'!D18 -> 969.10834 | E18: ='Income Statement'!E18 -> 995.30492 | F18: ='Income Statement'!F18 -> 926.9502 | G18: ='Income Statement'!G18 -> 1097.9136 | H18: ='Income Statement'!H18 -> 1298.6978 | I18: ='Income Statement'!I18 -> 1533.8683 | J18: ='Income Statement'!J18 -> 1807.0762 | M18: Cash Flow from Investing Activities | O18: ='Cash Flow Statement'!D24 -> -201.466 | P18: ='Cash Flow Statement'!E24 -> -310.735 | Q18: ='Cash Flow Statement'!F24 -> -351.35735 | R18: ='Cash Flow Statement'!G24 -> -404.6942 | S18: ='Cash Flow Statement'!H24 -> -467.02443 | T18: ='Cash Flow Statement'!I24 -> -539.88122 | U18: ='Cash Flow Statement'!J24 -> -625.06109
O19: ='Cash Flow Statement'!D25 -> 0 | P19: ='Cash Flow Statement'!E25 -> 0 | Q19: ='Cash Flow Statement'!F25 -> 0 | R19: ='Cash Flow Statement'!G25 -> 0 | S19: ='Cash Flow Statement'!H25 -> 0 | T19: ='Cash Flow Statement'!I25 -> 0 | U19: ='Cash Flow Statement'!J25 -> 0
B20: Income Taxes | C20: ='Income Statement'!C20 -> 175 | D20: ='Income Statement'!D20 -> 215 | E20: ='Income Statement'!E20 -> 255 | F20: ='Income Statement'!F20 -> 231.73755 | G20: ='Income Statement'!G20 -> 274.4784 | H20: ='Income Statement'!H20 -> 324.67445 | I20: ='Income Statement'!I20 -> 383.46707 | J20: ='Income Statement'!J20 -> 451.76904 | M20: Financing Activities | O20: ='Cash Flow Statement'!D26 -> 0 | P20: ='Cash Flow Statement'!E26 -> 0 | Q20: ='Cash Flow Statement'!F26 -> 0 | R20: ='Cash Flow Statement'!G26 -> 0 | S20: ='Cash Flow Statement'!H26 -> 0 | T20: ='Cash Flow Statement'!I26 -> 0 | U20: ='Cash Flow Statement'!J26 -> 0
B21: Net Income | C21: ='Income Statement'!C21 -> 774.5861 | D21: ='Income Statement'!D21 -> 754.10834 | E21: ='Income Statement'!E21 -> 740.30492 | F21: ='Income Statement'!F21 -> 695.21265 | G21: ='Income Statement'!G21 -> 823.4352 | H21: ='Income Statement'!H21 -> 974.02334 | I21: ='Income Statement'!I21 -> 1150.4012 | J21: ='Income Statement'!J21 -> 1355.3071 | M21: Proceeds from/ (repayment of) Revolving Credit Facility | O21: ='Cash Flow Statement'!D27 -> -100 | P21: ='Cash Flow Statement'!E27 -> -49 | Q21: ='Cash Flow Statement'!F27 -> 49.4693 | R21: ='Cash Flow Statement'!G27 -> -42.458335 | S21: ='Cash Flow Statement'!H27 -> -66.004154 | T21: ='Cash Flow Statement'!I27 -> 0 | U21: ='Cash Flow Statement'!J27 -> 0
M22: Issuance of Long Term Debt | O22: ='Cash Flow Statement'!D28 -> 0 | P22: ='Cash Flow Statement'!E28 -> 0 | Q22: ='Cash Flow Statement'!F28 -> 0 | R22: ='Cash Flow Statement'!G28 -> 0 | S22: ='Cash Flow Statement'!H28 -> 0 | T22: ='Cash Flow Statement'!I28 -> 0 | U22: ='Cash Flow Statement'!J28 -> 0
M23: (Repayment) of Long Term Debt | O23: ='Cash Flow Statement'!D29 -> -210 | P23: ='Cash Flow Statement'!E29 -> -355 | Q23: ='Cash Flow Statement'!F29 -> -300 | R23: ='Cash Flow Statement'!G29 -> -200 | S23: ='Cash Flow Statement'!H29 -> -100 | T23: ='Cash Flow Statement'!I29 -> -50 | U23: ='Cash Flow Statement'!J29 -> -50
B24: Outstanding Shares | C24: ='Income Statement'!C24 -> 99.245 | D24: ='Income Statement'!D24 -> 97.995 | E24: ='Income Statement'!E24 -> 96.61569 | F24: ='Income Statement'!F24 -> 94.909212 | G24: ='Income Statement'!G24 -> 93.490005 | H24: ='Income Statement'!H24 -> 92.305415 | I24: ='Income Statement'!I24 -> 91.313227 | J24: ='Income Statement'!J24 -> 90.478741 | M24: Issuance/ (Repurchase of) Equity | O24: ='Cash Flow Statement'!D30 -> -75 | P24: ='Cash Flow Statement'!E30 -> -80 | Q24: ='Cash Flow Statement'!F30 -> -100 | R24: ='Cash Flow Statement'!G30 -> -100 | S24: ='Cash Flow Statement'!H30 -> -100 | T24: ='Cash Flow Statement'!I30 -> -100 | U24: ='Cash Flow Statement'!J30 -> -100
B25: EPS | C25: ='Income Statement'!C26 -> 7.8047872 | D25: ='Income Statement'!D26 -> 7.6953757 | E25: ='Income Statement'!E26 -> 7.6623675 | F25: ='Income Statement'!F26 -> 7.325029 | G25: ='Income Statement'!G26 -> 8.8077357 | H25: ='Income Statement'!H26 -> 10.55218 | I25: ='Income Statement'!I26 -> 12.598408 | J25: ='Income Statement'!J26 -> 14.979288 | M25: Dividends | O25: ='Cash Flow Statement'!D31 -> -190 | P25: ='Cash Flow Statement'!E31 -> -230 | Q25: ='Cash Flow Statement'!F31 -> -208.79876 | R25: ='Cash Flow Statement'!G31 -> -248.94619 | S25: ='Cash Flow Statement'!H31 -> -296.64566 | T25: ='Cash Flow Statement'!I31 -> -351.99945 | U25: ='Cash Flow Statement'!J31 -> -416.36436
M26: Cash Flow from Financing Activities | O26: ='Cash Flow Statement'!D32 -> -575 | P26: ='Cash Flow Statement'!E32 -> -714 | Q26: ='Cash Flow Statement'!F32 -> -559.32946 | R26: ='Cash Flow Statement'!G32 -> -591.40453 | S26: ='Cash Flow Statement'!H32 -> -562.64982 | T26: ='Cash Flow Statement'!I32 -> -501.99945 | U26: ='Cash Flow Statement'!J32 -> -566.36436
O27: ='Cash Flow Statement'!D33 -> 0 | P27: ='Cash Flow Statement'!E33 -> 0 | Q27: ='Cash Flow Statement'!F33 -> 0 | R27: ='Cash Flow Statement'!G33 -> 0 | S27: ='Cash Flow Statement'!H33 -> 0 | T27: ='Cash Flow Statement'!I33 -> 0 | U27: ='Cash Flow Statement'!J33 -> 0
B28: Balance Sheet | M28: Net Change in Cash | O28: ='Cash Flow Statement'!D34 -> 58.108342 | P28: ='Cash Flow Statement'!E34 -> -36.895075 | Q28: ='Cash Flow Statement'!F34 -> -18.713267 | R28: ='Cash Flow Statement'!G34 -> -31.32094 | S28: ='Cash Flow Statement'!H34 -> 120.85192 | T28: ='Cash Flow Statement'!I34 -> 324.32827 | U28: ='Cash Flow Statement'!J34 -> 425.66635
C29: Actuals | F29: Forecast | M29: Beginning Cash Balance | O29: ='Cash Flow Statement'!D35 -> 27.5 | P29: ='Cash Flow Statement'!E35 -> 85.608342 | Q29: ='Cash Flow Statement'!F35 -> 48.713267 | R29: ='Cash Flow Statement'!G35 -> 30 | S29: ='Cash Flow Statement'!H35 -> -1.3209401 | T29: ='Cash Flow Statement'!I35 -> 119.53098 | U29: ='Cash Flow Statement'!J35 -> 443.85925
B30: ($ in Million Except Per Share Amounts) | C30: Historical 1 | D30: Historical 2 | E30: Historical 3 | F30: Forecast 1 | G30: Forecast 2 | H30: Forecast 3 | I30: Forecast 4 | J30: Forecast 5 | M30: Ending Cash Balance | N30: ='Cash Flow Statement'!C36 -> 27.5 | O30: ='Cash Flow Statement'!D36 -> 85.608342 | P30: ='Cash Flow Statement'!E36 -> 48.713267 | Q30: ='Cash Flow Statement'!F36 -> 30 | R30: ='Cash Flow Statement'!G36 -> -1.3209401 | S30: ='Cash Flow Statement'!H36 -> 119.53098 | T30: ='Cash Flow Statement'!I36 -> 443.85925 | U30: ='Cash Flow Statement'!J36 -> 869.5256
B32: Current Assets
B33: Cash & Cash Equivalents | C33: ='Balance Sheet'!C7 -> 27.5 | D33: ='Balance Sheet'!D7 -> 85.608342 | E33: ='Balance Sheet'!E7 -> 48.713267 | F33: ='Balance Sheet'!F7 -> 30 | G33: ='Balance Sheet'!G7 -> -1.3209401 | H33: ='Balance Sheet'!H7 -> 119.53098 | I33: ='Balance Sheet'!I7 -> 443.85925 | J33: ='Balance Sheet'!J7 -> 869.5256
B34: Marketable Securities | C34: ='Balance Sheet'!C8 -> 40 | D34: ='Balance Sheet'!D8 -> 50 | E34: ='Balance Sheet'!E8 -> 60 | F34: ='Balance Sheet'!F8 -> 70 | G34: ='Balance Sheet'!G8 -> 80 | H34: ='Balance Sheet'!H8 -> 90 | I34: ='Balance Sheet'!I8 -> 100 | J34: ='Balance Sheet'!J8 -> 110
B35: Receivables | C35: ='Balance Sheet'!C9 -> 462.9 | D35: ='Balance Sheet'!D9 -> 473.7 | E35: ='Balance Sheet'!E9 -> 473 | F35: ='Balance Sheet'!F9 -> 474.07828 | G35: ='Balance Sheet'!G9 -> 552.76278 | H35: ='Balance Sheet'!H9 -> 644.71465 | I35: ='Balance Sheet'!I9 -> 752.19568 | J35: ='Balance Sheet'!J9 -> 877.8562
B36: Inventory | C36: ='Balance Sheet'!C10 -> 327 | D36: ='Balance Sheet'!D10 -> 350.2 | E36: ='Balance Sheet'!E10 -> 383.8 | F36: ='Balance Sheet'!F10 -> 411.32788 | G36: ='Balance Sheet'!G10 -> 479.44348 | H36: ='Balance Sheet'!H10 -> 559.03134 | I36: ='Balance Sheet'!I10 -> 652.04664 | J36: ='Balance Sheet'!J10 -> 760.78048
B37: Other Current Assets | C37: ='Balance Sheet'!C11 -> 87.4 | D37: ='Balance Sheet'!D11 -> 82.8 | E37: ='Balance Sheet'!E11 -> 83.5 | F37: ='Balance Sheet'!F11 -> 82.39932 | G37: ='Balance Sheet'!G11 -> 96.075436 | H37: ='Balance Sheet'!H11 -> 112.05755 | I37: ='Balance Sheet'!I11 -> 130.73877 | J37: ='Balance Sheet'!J11 -> 152.57977
B38: Total Current Assets | C38: ='Balance Sheet'!C12 -> 944.8 | D38: ='Balance Sheet'!D12 -> 1042.3083 | E38: ='Balance Sheet'!E12 -> 1049.0133 | F38: ='Balance Sheet'!F12 -> 1067.8055 | G38: ='Balance Sheet'!G12 -> 1206.9608 | H38: ='Balance Sheet'!H12 -> 1525.3345 | I38: ='Balance Sheet'!I12 -> 2078.8403 | J38: ='Balance Sheet'!J12 -> 2770.742
B40: Long Term Securities | C40: ='Balance Sheet'!C14 -> 160 | D40: ='Balance Sheet'!D14 -> 180 | E40: ='Balance Sheet'!E14 -> 200 | F40: ='Balance Sheet'!F14 -> 220 | G40: ='Balance Sheet'!G14 -> 240 | H40: ='Balance Sheet'!H14 -> 260 | I40: ='Balance Sheet'!I14 -> 280 | J40: ='Balance Sheet'!J14 -> 300
B42: Land | C42: ='Balance Sheet'!C16 -> 30 | D42: ='Balance Sheet'!D16 -> 30 | E42: ='Balance Sheet'!E16 -> 30 | F42: ='Balance Sheet'!F16 -> 30 | G42: ='Balance Sheet'!G16 -> 30 | H42: ='Balance Sheet'!H16 -> 30 | I42: ='Balance Sheet'!I16 -> 30 | J42: ='Balance Sheet'!J16 -> 30
B43: Machinery and equipment | C43: ='Balance Sheet'!C17 -> 630 | D43: ='Balance Sheet'!D17 -> 700 | E43: ='Balance Sheet'!E17 -> 875 | F43: ='Balance Sheet'!F17 -> 1080.9983 | G43: ='Balance Sheet'!G17 -> 1321.1869 | H43: ='Balance Sheet'!H17 -> 1601.3308 | I43: ='Balance Sheet'!I17 -> 1928.1777 | J43: ='Balance Sheet'!J17 -> 2309.6271
...

Sheet Income Statement
A1: Big Books Company
B2: Income Statement
C3: Actuals | F3: Forecast
B4: ($ in Million Except Per Share Amounts) | C4: Historical 1 | D4: Historical 2 | E4: Historical 3 | F4: Forecast 1 | G4: Forecast 2 | H4: Forecast 3 | I4: Forecast 4 | J4: Forecast 5
B5: Net Sales | C5: 2904.94 | D5: 3408 | E5: 3958.96 | F5: ='Revenue and Cost Forecast'!F34 -> 4119.966 | G5: ='Revenue and Cost Forecast'!G34 -> 4803.7718 | H5: ='Revenue and Cost Forecast'!H34 -> 5602.8773 | I5: ='Revenue and Cost Forecast'!I34 -> 6536.9387 | J5: ='Revenue and Cost Forecast'!J34 -> 7628.9884
B6: Cost of Sales | C6: 1494.8366 | D6: 1866.1246 | E6: 2309.7272 | F6: ='Revenue and Cost Forecast'!F50 -> 2502.2446 | G6: ='Revenue and Cost Forecast'!G50 -> 2916.6145 | H6: ='Revenue and Cost Forecast'!H50 -> 3400.774 | I6: ='Revenue and Cost Forecast'!I50 -> 3966.6171 | J6: ='Revenue and Cost Forecast'!J50 -> 4628.0813
B7: Gross Profit | C7: =C5-C6 -> 1410.1034 | D7: =D5-D6 -> 1541.8754 | E7: =E5-E6 -> 1649.2328 | F7: =F5-F6 -> 1617.7214 | G7: =G5-G6 -> 1887.1573 | H7: =H5-H6 -> 2202.1033 | I7: =I5-I6 -> 2570.3216 | J7: =J5-J6 -> 3000.9071
B9: Selling, General & Admin Costs | C9: 305.14255 | D9: 388.2872 | E9: 448.0675 | F9: ='Revenue and Cost Forecast'!F65 -> 463.83868 | G9: ='Revenue and Cost Forecast'!G65 -> 540.94103 | H9: ='Revenue and Cost Forecast'!H65 -> 631.05976 | I9: ='Revenue and Cost Forecast'!I65 -> 736.41607 | J9: ='Revenue and Cost Forecast'!J65 -> 859.61298
B10: EBITDA | C10: =C7-C9 -> 1104.9608 | D10: =D7-D9 -> 1153.5882 | E10: =E7-E9 -> 1201.1653 | F10: =F7-F9 -> 1153.8827 | G10: =G7-G9 -> 1346.2162 | H10: =H7-H9 -> 1571.0435 | I10: =I7-I9 -> 1833.9055 | J10: =J7-J9 -> 2141.2941
B12: Depreciation | C12: 101.9 | D12: 123.1 | E12: 140 | F12: ='Depreciation Capex Forecast'!F57 -> 151.53313 | G12: ='Depreciation Capex Forecast'!G57 -> 179.55514 | H12: ='Depreciation Capex Forecast'!H57 -> 212.23859 | I12: ='Depreciation Capex Forecast'!I57 -> 250.37073 | J12: ='Depreciation Capex Forecast'!J57 -> 294.87316
B13: Amortization | C13: 9.367 | D13: 10.666 | E13: 13.035 | F13: ='Amortization Forecast'!F28 -> 13.295973 | G13: ='Amortization Forecast'!G28 -> 17.13899 | H13: ='Amortization Forecast'!H28 -> 21.621292 | I13: ='Amortization Forecast'!I28 -> 26.850843 | J13: ='Amortization Forecast'!J28 -> 32.954034
B14: EBIT | C14: =C10-C12-C13 -> 993.69382 | D14: =D10-D12-D13 -> 1019.8222 | E14: =E10-E12-E13 -> 1048.1303 | F14: =F10-F12-F13 -> 989.05358 | G14: =G10-G12-G13 -> 1149.5221 | H14: =H10-H12-H13 -> 1337.1836 | I14: =I10-I12-I13 -> 1556.684 | J14: =J10-J12-J13 -> 1813.4669
B16: Interest Expense | C16: 44.10772 | D16: 60.11464 | E16: 63.765 | F16: ='Debt Forecast'!F48 -> 73.105859 | G16: ='Debt Forecast'!G48 -> 62.785391 | H16: ='Debt Forecast'!H48 -> 52.279533 | I16: ='Debt Forecast'!I48 -> 45.45 | J16: ='Debt Forecast'!J48 -> 43.2
B17: Interest Income | C17: 0 | D17: 9.4007832 | E17: 10.939602 | F17: ='Debt Forecast'!F57 -> 11.002482 | G17: ='Debt Forecast'!G57 -> 11.176884 | H17: ='Debt Forecast'!H57 -> 13.793676 | I17: ='Debt Forecast'!I57 -> 22.634329 | J17: ='Debt Forecast'!J57 -> 36.809235
B18: Pretax Income | C18: =C14-C16+C17 -> 949.5861 | D18: =D14-D16+D17 -> 969.10834 | E18: =E14-E16+E17 -> 995.30492 | F18: =F14-F16+F17 -> 926.9502 | G18: =G14-G16+G17 -> 1097.9136 | H18: =H14-H16+H17 -> 1298.6978 | I18: =I14-I16+I17 -> 1533.8683 | J18: =J14-J16+J17 -> 1807.0762
B20: Income Taxes | C20: 175 | D20: 215 | E20: 255 | F20: =F18*F23 -> 231.73755 | G20: =G18*G23 -> 274.4784 | H20: =H18*H23 -> 324.67445 | I20: =I18*I23 -> 383.46707 | J20: =J18*J23 -> 451.76904
B21: Net Income | C21: =C18-C20 -> 774.5861 | D21: =D18-D20 -> 754.10834 | E21: =E18-E20 -> 740.30492 | F21: =F18-F20 -> 695.21265 | G21: =G18-G20 -> 823.4352 | H21: =H18-H20 -> 974.02334 | I21: =I18-I20 -> 1150.4012 | J21: =J18-J20 -> 1355.3071
B23: Effective Tax Rate | C23: =C20/C18 -> 0.18429082 | D23: =D20/D18 -> 0.22185342 | E23: =E20/E18 -> 0.25620289 | F23: 0.25 | G23: 0.25 | H23: 0.25 | I23: 0.25 | J23: 0.25
B24: Outstanding Shares | C24: 99.245 | D24: 97.995 | E24: 96.61569 | F24: ='Shareholder''s Equity Forecast'!F25 -> 94.909212 | G24: ='Shareholder''s Equity Forecast'!G25 -> 93.490005 | H24: ='Shareholder''s Equity Forecast'!H25 -> 92.305415 | I24: ='Shareholder''s Equity Forecast'!I25 -> 91.313227 | J24: ='Shareholder''s Equity Forecast'!J25 -> 90.478741
B26: Earnings Per Share | C26: =C21/C24 -> 7.8047872 | D26: =D21/D24 -> 7.6953757 | E26: =E21/E24 -> 7.6623675 | F26: =F21/F24 -> 7.325029 | G26: =G21/G24 -> 8.8077357 | H26: =H21/H24 -> 10.55218 | I26: =I21/I24 -> 12.598408 | J26: =J21/J24 -> 14.979288
B28: Dividends | C28: 150 | D28: 190 | E28: 230 | F28: ='Shareholder''s Equity Forecast'!F7 -> 208.56379 | G28: ='Shareholder''s Equity Forecast'!G7 -> 247.03056 | H28: ='Shareholder''s Equity Forecast'!H7 -> 292.207 | I28: ='Shareholder''s Equity Forecast'!I7 -> 345.12036 | J28: ='Shareholder''s Equity Forecast'!J7 -> 406.59214
B29: Dividend Per Share | C29: =C28/C24 -> 1.5114112 | D29: =D28/D24 -> 1.9388744 | E29: =E28/E24 -> 2.3805657 | F29: =F28/F24 -> 2.1975085 | G29: =G28/G24 -> 2.6423205 | H29: =H28/H24 -> 3.1656539 | I29: =I28/I24 -> 3.7795222 | J29: =J28/J24 -> 4.4937864

Sheet Balance Sheet
A1: Big Books Company
B2: Balance Sheet
C3: Actuals | F3: Forecast
B4: ($ in Million Except Per Share Amounts) | C4: Historical 1 | D4: Historical 2 | E4: Historical 3 | F4: Forecast 1 | G4: Forecast 2 | H4: Forecast 3 | I4: Forecast 4 | J4: Forecast 5
B6: Current Assets
B7: Cash & Cash Equivalents | C7: 27.5 | D7: 85.608342 | E7: 48.713267 | F7: ='Cash Flow Statement'!F36 -> 30 | G7: ='Cash Flow Statement'!G36 -> -1.3209401 | H7: ='Cash Flow Statement'!H36 -> 119.53098 | I7: ='Cash Flow Statement'!I36 -> 443.85925 | J7: ='Cash Flow Statement'!J36 -> 869.5256
B8: Marketable Securities | C8: 40 | D8: 50 | E8: 60 | F8: ='Other Assets & Liabilities'!F7 -> 70 | G8: ='Other Assets & Liabilities'!G7 -> 80 | H8: ='Other Assets & Liabilities'!H7 -> 90 | I8: ='Other Assets & Liabilities'!I7 -> 100 | J8: ='Other Assets & Liabilities'!J7 -> 110
B9: Receivables | C9: 462.9 | D9: 473.7 | E9: 473 | F9: ='Working Capital Forecast'!F7 -> 474.07828 | G9: ='Working Capital Forecast'!G7 -> 552.76278 | H9: ='Working Capital Forecast'!H7 -> 644.71465 | I9: ='Working Capital Forecast'!I7 -> 752.19568 | J9: ='Working Capital Forecast'!J7 -> 877.8562
B10: Inventory | C10: 327 | D10: 350.2 | E10: 383.8 | F10: ='Working Capital Forecast'!F8 -> 411.32788 | G10: ='Working Capital Forecast'!G8 -> 479.44348 | H10: ='Working Capital Forecast'!H8 -> 559.03134 | I10: ='Working Capital Forecast'!I8 -> 652.04664 | J10: ='Working Capital Forecast'!J8 -> 760.78048
B11: Other Current Assets | C11: 87.4 | D11: 82.8 | E11: 83.5 | F11: ='Working Capital Forecast'!F9 -> 82.39932 | G11: ='Working Capital Forecast'!G9 -> 96.075436 | H11: ='Working Capital Forecast'!H9 -> 112.05755 | I11: ='Working Capital Forecast'!I9 -> 130.73877 | J11: ='Working Capital Forecast'!J9 -> 152.57977
B12: Total Current Assets | C12: =SUM(C7:C11) -> 944.8 | D12: =SUM(D7:D11) -> 1042.3083 | E12: =SUM(E7:E11) -> 1049.0133 | F12: =SUM(F7:F11) -> 1067.8055 | G12: =SUM(G7:G11) -> 1206.9608 | H12: =SUM(H7:H11) -> 1525.3345 | I12: =SUM(I7:I11) -> 2078.8403 | J12: =SUM(J7:J11) -> 2770.742
B14: Long Term Securities | C14: 160 | D14: 180 | E14: 200 | F14: ='Other Assets & Liabilities'!F8 -> 220 | G14: ='Other Assets & Liabilities'!G8 -> 240 | H14: ='Other Assets & Liabilities'!H8 -> 260 | I14: ='Other Assets & Liabilities'!I8 -> 280 | J14: ='Other Assets & Liabilities'!J8 -> 300
B16: Land | C16: 30 | D16: 30 | E16: 30 | F16: ='Depreciation Capex Forecast'!F7 -> 30 | G16: ='Depreciation Capex Forecast'!G7 -> 30 | H16: ='Depreciation Capex Forecast'!H7 -> 30 | I16: ='Depreciation Capex Forecast'!I7 -> 30 | J16: ='Depreciation Capex Forecast'!J7 -> 30
B17: Machinery and equipment | C17: =550+80 -> 630 | D17: 700 | E17: 875 | F17: ='Depreciation Capex Forecast'!F8 -> 1080.9983 | G17: ='Depreciation Capex Forecast'!G8 -> 1321.1869 | H17: ='Depreciation Capex Forecast'!H8 -> 1601.3308 | I17: ='Depreciation Capex Forecast'!I8 -> 1928.1777 | J17: ='Depreciation Capex Forecast'!J8 -> 2309.6271
B18: Automobiles and trucks | C18: 250 | D18: 325 | E18: 400 | F18: ='Depreciation Capex Forecast'!F9 -> 482.39932 | G18: ='Depreciation Capex Forecast'!G9 -> 578.47476 | H18: ='Depreciation Capex Forecast'!H9 -> 690.5323 | I18: ='Depreciation Capex Forecast'!I9 -> 821.27107 | J18: ='Depreciation Capex Forecast'!J9 -> 973.85084
B19: Gross PPE | C19: =SUM(C16:C18) -> 910 | D19: =SUM(D16:D18) -> 1055 | E19: =SUM(E16:E18) -> 1305 | F19: =SUM(F16:F18) -> 1593.3976 | G19: =SUM(G16:G18) -> 1929.6616 | H19: =SUM(H16:H18) -> 2321.8631 | I19: =SUM(I16:I18) -> 2779.4488 | J19: =SUM(J16:J18) -> 3313.4779
B20: Accumulated Depreciation | C20: -101.9 | D20: -225 | E20: -365 | F20: =E20-'Depreciation Capex Forecast'!F57 -> -516.53313 | G20: =F20-'Depreciation Capex Forecast'!G57 -> -696.08827 | H20: =G20-'Depreciation Capex Forecast'!H57 -> -908.32686 | I20: =H20-'Depreciation Capex Forecast'!I57 -> -1158.6976 | J20: =I20-'Depreciation Capex Forecast'!J57 -> -1453.5708
B21: Net PPE | C21: =C19+C20 -> 808.1 | D21: =D19+D20 -> 830 | E21: =E19+E20 -> 940 | F21: =F19+F20 -> 1076.8645 | G21: =G19+G20 -> 1233.5734 | H21: =H19+H20 -> 1413.5362 | I21: =I19+I20 -> 1620.7512 | J21: =J19+J20 -> 1859.9072
B23: Other Assets
B24: Intangibles, net | C24: 46.5 | D24: 62.3 | E24: 80 | F24: ='Amortization Forecast'!F13 -> 99.663755 | G24: ='Amortization Forecast'!G13 -> 120.95494 | H24: ='Amortization Forecast'!H13 -> 144.15667 | I24: ='Amortization Forecast'!I13 -> 169.60133 | J24: ='Amortization Forecast'!J13 -> 197.67921
B25: Goodwill | C25: 1671.7 | D25: 1671.7 | E25: 1671.7 | F25: ='Other Assets & Liabilities'!C6 -> 1671.7 | G25: ='Other Assets & Liabilities'!D6 -> 1671.7 | H25: ='Other Assets & Liabilities'!E6 -> 1671.7 | I25: ='Other Assets & Liabilities'!F6 -> 1671.7 | J25: ='Other Assets & Liabilities'!G6 -> 1671.7
B27: Total Assets | C27: =C12+C21+C24+C25+C14 -> 3631.1 | D27: =D12+D21+D24+D25+D14 -> 3786.3083 | E27: =E12+E21+E24+E25+E14 -> 3940.7133 | F27: =F12+F21+F24+F25+F14 -> 4136.0337 | G27: =G12+G21+G24+G25+G14 -> 4473.1891 | H27: =H12+H21+H24+H25+H14 -> 5014.7274 | I27: =I12+I21+I24+I25+I14 -> 5820.8928 | J27: =J12+J21+J24+J25+J14 -> 6800.0284
B29: Current Liabilities
B30: Accounts Payable | C30: 206.4 | D30: 221.4 | E30: 279.1 | F30: ='Working Capital Forecast'!F12 -> 308.49591 | G30: ='Working Capital Forecast'!G12 -> 359.58261 | H30: ='Working Capital Forecast'!H12 -> 419.27351 | I30: ='Working Capital Forecast'!I12 -> 489.03498 | J30: ='Working Capital Forecast'!J12 -> 570.58536
B31: Accrued Liabilities | C31: 180.7 | D31: 161.3 | E31: 176.7 | F31: ='Working Capital Forecast'!F13 -> 200.17957 | G31: ='Working Capital Forecast'!G13 -> 233.32916 | H31: ='Working Capital Forecast'!H13 -> 272.06192 | I31: ='Working Capital Forecast'!I13 -> 317.32937 | J31: ='Working Capital Forecast'!J13 -> 370.2465
B32: Other Current Liabilities | C32: 68.3 | D32: 62.8 | E32: 81.8 | F32: ='Working Capital Forecast'!F14 -> 87.578562 | G32: ='Working Capital Forecast'!G14 -> 102.08151 | H32: ='Working Capital Forecast'!H14 -> 119.02709 | I32: ='Working Capital Forecast'!I14 -> 138.8316 | J32: ='Working Capital Forecast'!J14 -> 161.98284
B33: Total Current Liabilities | C33: =SUM(C30:C32) -> 455.4 | D33: =SUM(D30:D32) -> 445.5 | E33: =SUM(E30:E32) -> 537.6 | F33: =SUM(F30:F32) -> 596.25405 | G33: =SUM(G30:G32) -> 694.99328 | H33: =SUM(H30:H32) -> 810.36252 | I33: =SUM(I30:I32) -> 945.19594 | J33: =SUM(J30:J32) -> 1102.8147
B35: Loan Funds
B36: Revolving Credit Facility | C36: 250 | D36: 150 | E36: 101 | F36: ='Debt Forecast'!F28 -> 150.4693 | G36: ='Debt Forecast'!G28 -> 138.18131 | H36: ='Debt Forecast'!H28 -> 0 | I36: ='Debt Forecast'!I28 -> 0 | J36: ='Debt Forecast'!J28 -> 0
B37: Long Term Debt | C37: 2200 | D37: 1990 | E37: =1535+100 -> 1635 | F37: ='Debt Forecast'!F34 -> 1335 | G37: ='Debt Forecast'!G34 -> 1135 | H37: ='Debt Forecast'!H34 -> 1035 | I37: ='Debt Forecast'!I34 -> 985 | J37: ='Debt Forecast'!J34 -> 935
B38: Total Loan Funds | C38: =SUM(C36:C37) -> 2450 | D38: =SUM(D36:D37) -> 2140 | E38: =SUM(E36:E37) -> 1736 | F38: =SUM(F36:F37) -> 1485.4693 | G38: =SUM(G36:G37) -> 1273.1813 | H38: =SUM(H36:H37) -> 1035 | I38: =SUM(I36:I37) -> 985 | J38: =SUM(J36:J37) -> 935
B40: Other Long Term Liabilities | C40: 153 | D40: 157.3 | E40: 187.1 | F40: ='Other Assets & Liabilities'!F9 -> 187.1 | G40: ='Other Assets & Liabilities'!G9 -> 187.1 | H40: ='Other Assets & Liabilities'!H9 -> 187.1 | I40: ='Other Assets & Liabilities'!I9 -> 187.1 | J40: ='Other Assets & Liabilities'!J9 -> 187.1
B41: Post retirement Pension Cost | C41: 72.7 | D41: 54.4 | E41: 60.6 | F41: ='Other Assets & Liabilities'!F10 -> 60.6 | G41: ='Other Assets & Liabilities'!G10 -> 60.6 | H41: ='Other Assets & Liabilities'!H10 -> 60.6 | I41: ='Other Assets & Liabilities'!I10 -> 60.6 | J41: ='Other Assets & Liabilities'!J10 -> 60.6
B43: Common Stock & APIC | C43: 1000 | D43: 1000 | E43: 1000 | F43: ='Shareholder''s Equity Forecast'!F12 -> 1000 | G43: ='Shareholder''s Equity Forecast'!G12 -> 1000 | H43: ='Shareholder''s Equity Forecast'!H12 -> 1000 | I43: ='Shareholder''s Equity Forecast'!I12 -> 1000 | J43: ='Shareholder''s Equity Forecast'!J12 -> 1000
B44: Treasury Stock | C44: -1500 | D44: -1575 | E44: -1655 | F44: ='Shareholder''s Equity Forecast'!F13 -> -1755 | G44: ='Shareholder''s Equity Forecast'!G13 -> -1855 | H44: ='Shareholder''s Equity Forecast'!H13 -> -1955 | I44: ='Shareholder''s Equity Forecast'!I13 -> -2055 | J44: ='Shareholder''s Equity Forecast'!J13 -> -2155
B45: Retained Earnings | C45: 1000 | D45: 1564.1083 | E45: 2074.4133 | F45: ='Shareholder''s Equity Forecast'!F14 -> 2561.0621 | G45: ='Shareholder''s Equity Forecast'!G14 -> 3137.4668 | H45: ='Shareholder''s Equity Forecast'!H14 -> 3819.2831 | I45: ='Shareholder''s Equity Forecast'!I14 -> 4624.5639 | J45: ='Shareholder''s Equity Forecast'!J14 -> 5573.2789
B46: Accumulated Other Comprehensive Income | C46: 0 | D46: 0 | E46: 0 | F46: ='Shareholder''s Equity Forecast'!F15 -> 0 | G46: ='Shareholder''s Equity Forecast'!G15 -> 0 | H46: ='Shareholder''s Equity Forecast'!H15 -> 0 | I46: ='Shareholder''s Equity Forecast'!I15 -> 0 | J46: ='Shareholder''s Equity Forecast'!J15 -> 0
B47: Shareholder's Equity | C47: =SUM(C43:C46) -> 500 | D47: =SUM(D43:D46) -> 989.10834 | E47: =SUM(E43:E46) -> 1419.4133 | F47: =SUM(F43:F46) -> 1806.0621 | G47: =SUM(G43:G46) -> 2282.4668 | H47: =SUM(H43:H46) -> 2864.2831 | I47: =SUM(I43:I46) -> 3569.5639 | J47: =SUM(J43:J46) -> 4418.2789
B49: Total Liabilities & Equity | C49: =C47+C41+C40+C38+C33 -> 3631.1 | D49: =D47+D41+D40+D38+D33 -> 3786.3083 | E49: =E47+E41+E40+E38+E33 -> 3940.7133 | F49: =F47+F41+F40+F38+F33 -> 4135.4855 | G49: =G47+G41+G40+G38+G33 -> 4498.3414 | H49: =H47+H41+H40+H38+H33 -> 4957.3456 | I49: =I47+I41+I40+I38+I33 -> 5747.4599 | J49: =J47+J41+J40+J38+J33 -> 6703.7936
B52: Check | C52: =C49-C27 -> 0 | D52: =D49-D27 -> 0 | E52: =E49-E27 -> 0

Sheet Cash Flow Statement
A1: Big Books Company
B2: Cash Flow Statement
C3: Actuals | F3: Forecast
B4: ($ in Million Except Per Share Amounts) | C4: Historical 1 | D4: Historical 2 | E4: Historical 3 | F4: Forecast 1 | G4: Forecast 2 | H4: Forecast 3 | I4: Forecast 4 | J4: Forecast 5
B5: Operating Activities
B6: Net Income | D6: 754.10834 | E6: 740.30492 | F6: ='Income Statement'!F21 -> 695.99587 | G6: ='Income Statement'!G21 -> 829.82064 | H6: ='Income Statement'!H21 -> 988.81888 | I6: ='Income Statement'!I21 -> 1173.3315 | J6: ='Income Statement'!J21 -> 1387.8812
B7: Add Depreciation | D7: 123.1 | E7: 140 | F7: ='Income Statement'!F12 -> 151.53313 | G7: ='Income Statement'!G12 -> 179.55514 | H7: ='Income Statement'!H12 -> 212.23859 | I7: ='Income Statement'!I12 -> 250.37073 | J7: ='Income Statement'!J12 -> 294.87316
B8: Add Amortization | D8: 10.666 | E8: 13.035 | F8: ='Income Statement'!F13 -> 13.295973 | G8: ='Income Statement'!G13 -> 17.13899 | H8: ='Income Statement'!H13 -> 21.621292 | I8: ='Income Statement'!I13 -> 26.850843 | J8: ='Income Statement'!J13 -> 32.954034
B9: Change in Working Capital
B10: Change in Receivable | D10: -10.8 | E10: 0.7 | F10: ='Working Capital Forecast'!F35 -> -1.078279 | G10: ='Working Capital Forecast'!G35 -> -78.684503 | H10: ='Working Capital Forecast'!H35 -> -91.951864 | I10: ='Working Capital Forecast'!I35 -> -107.48104 | J10: ='Working Capital Forecast'!J35 -> -125.66052
B11: change in Inventory | D11: -23.2 | E11: -33.6 | F11: ='Working Capital Forecast'!F36 -> -27.527884 | G11: ='Working Capital Forecast'!G36 -> -68.1156 | H11: ='Working Capital Forecast'!H36 -> -79.587859 | I11: ='Working Capital Forecast'!I36 -> -93.015299 | J11: ='Working Capital Forecast'!J36 -> -108.73384
B12: Change in Other Current Assets | D12: 4.6 | E12: -0.7 | F12: ='Working Capital Forecast'!F37 -> 1.1006801 | G12: ='Working Capital Forecast'!G37 -> -13.676116 | H12: ='Working Capital Forecast'!H37 -> -15.98211 | I12: ='Working Capital Forecast'!I37 -> -18.681228 | J12: ='Working Capital Forecast'!J37 -> -21.840994
B13: Change in Accounts Payable | D13: 15 | E13: 57.7 | F13: ='Working Capital Forecast'!F38 -> 29.395913 | G13: ='Working Capital Forecast'!G38 -> 51.0867 | H13: ='Working Capital Forecast'!H38 -> 59.690894 | I13: ='Working Capital Forecast'!I38 -> 69.761474 | J13: ='Working Capital Forecast'!J38 -> 81.550381
B14: Change in Accrued Liabilities | D14: -19.4 | E14: 15.4 | F14: ='Working Capital Forecast'!F39 -> 23.47957 | G14: ='Working Capital Forecast'!G39 -> 33.149592 | H14: ='Working Capital Forecast'!H39 -> 38.732758 | I14: ='Working Capital Forecast'!I39 -> 45.267445 | J14: ='Working Capital Forecast'!J39 -> 52.917136
B15: Change in Other Current Liabilities | D15: -5.5 | E15: 19 | F15: ='Working Capital Forecast'!F40 -> 5.778562 | G15: ='Working Capital Forecast'!G40 -> 14.502947 | H15: ='Working Capital Forecast'!H40 -> 16.945582 | I15: ='Working Capital Forecast'!I40 -> 19.804507 | J15: ='Working Capital Forecast'!J40 -> 23.151247
B16: Change in Assets & Liabilities (if any) | D16: -14 | E16: 36 | F16: =('Balance Sheet'!F40-'Balance Sheet'!E40)+('Balance Sheet'!F41-'Balance Sheet'!E41) -> 0 | G16: =('Balance Sheet'!G40-'Balance Sheet'!F40)+('Balance Sheet'!G41-'Balance Sheet'!F41) -> 0 | H16: =('Balance Sheet'!H40-'Balance Sheet'!G40)+('Balance Sheet'!H41-'Balance Sheet'!G41) -> 0 | I16: =('Balance Sheet'!I40-'Balance Sheet'!H40)+('Balance Sheet'!I41-'Balance Sheet'!H41) -> 0 | J16: =('Balance Sheet'!J40-'Balance Sheet'!I40)+('Balance Sheet'!J41-'Balance Sheet'!I41) -> 0
B17: Cash Flow from Operating Activities | D17: =SUM(D6:D16) -> 834.57434 | E17: =SUM(E6:E16) -> 987.83992 | F17: =SUM(F6:F16) -> 891.97354 | G17: =SUM(G6:G16) -> 964.77779 | H17: =SUM(H6:H16) -> 1150.5262 | I17: =SUM(I6:I16) -> 1366.2089 | J17: =SUM(J6:J16) -> 1617.0918
B19: Investment Activities
B20: Purchase of Marketable Securities | D20: -10 | E20: -10 | F20: =-('Balance Sheet'!F8-'Balance Sheet'!E8) -> -10 | G20: =-('Balance Sheet'!G8-'Balance Sheet'!F8) -> -10 | H20: =-('Balance Sheet'!H8-'Balance Sheet'!G8) -> -10 | I20: =-('Balance Sheet'!I8-'Balance Sheet'!H8) -> -10 | J20: =-('Balance Sheet'!J8-'Balance Sheet'!I8) -> -10
B21: Purchase of Long Term Securities | D21: -20 | E21: -20 | F21: =-('Balance Sheet'!F14-'Balance Sheet'!E14) -> -20 | G21: =-('Balance Sheet'!G14-'Balance Sheet'!F14) -> -20 | H21: =-('Balance Sheet'!H14-'Balance Sheet'!G14) -> -20 | I21: =-('Balance Sheet'!I14-'Balance Sheet'!H14) -> -20 | J21: =-('Balance Sheet'!J14-'Balance Sheet'!I14) -> -20
B22: Capital Expenditures | D22: -145 | E22: -250 | F22: =-'Depreciation Capex Forecast'!F18 -> -288.39762 | G22: =-'Depreciation Capex Forecast'!G18 -> -336.26403 | H22: =-'Depreciation Capex Forecast'!H18 -> -392.20141 | I22: =-'Depreciation Capex Forecast'!I18 -> -457.58571 | J22: =-'Depreciation Capex Forecast'!J18 -> -534.02919
B23: Additions to Intangibles | D23: -26.466 | E23: -30.735 | F23: =-'Amortization Forecast'!F7 -> -32.959728 | G23: =-'Amortization Forecast'!G7 -> -38.430174 | H23: =-'Amortization Forecast'!H7 -> -44.823018 | I23: =-'Amortization Forecast'!I7 -> -52.295509 | J23: =-'Amortization Forecast'!J7 -> -61.031907
B24: Cash Flow from Investing Activities | D24: =SUM(D20:D23) -> -201.466 | E24: =SUM(E20:E23) -> -310.735 | F24: =SUM(F20:F23) -> -351.35735 | G24: =SUM(G20:G23) -> -404.6942 | H24: =SUM(H20:H23) -> -467.02443 | I24: =SUM(I20:I23) -> -539.88122 | J24: =SUM(J20:J23) -> -625.06109
B26: Financing Activities
B27: Proceeds from/ (repayment of) Revolving Credit Facility | D27: -100 | E27: -49 | F27: ='Debt Forecast'!F27 -> 49.4693 | G27: ='Debt Forecast'!G27 -> -42.458335 | H27: ='Debt Forecast'!H27 -> -66.004154 | I27: ='Debt Forecast'!I27 -> 0 | J27: ='Debt Forecast'!J27 -> 0
B28: Issuance of Long Term Debt | D28: 0 | E28: 0 | F28: 0 | G28: 0 | H28: 0 | I28: 0 | J28: 0
B29: (Repayment) of Long Term Debt | D29: -210 | E29: -355 | F29: ='Debt Forecast'!F33 -> -300 | G29: ='Debt Forecast'!G33 -> -200 | H29: ='Debt Forecast'!H33 -> -100 | I29: ='Debt Forecast'!I33 -> -50 | J29: ='Debt Forecast'!J33 -> -50
B30: Issuance/ (Repurchase of) Equity | D30: -75 | E30: -80 | F30: ='Shareholder''s Equity Forecast'!F19 -> -100 | G30: ='Shareholder''s Equity Forecast'!G19 -> -100 | H30: ='Shareholder''s Equity Forecast'!H19 -> -100 | I30: ='Shareholder''s Equity Forecast'!I19 -> -100 | J30: ='Shareholder''s Equity Forecast'!J19 -> -100
B31: Dividends | D31: -190 | E31: -230 | F31: =-'Shareholder''s Equity Forecast'!F7 -> -208.79876 | G31: =-'Shareholder''s Equity Forecast'!G7 -> -248.94619 | H31: =-'Shareholder''s Equity Forecast'!H7 -> -296.64566 | I31: =-'Shareholder''s Equity Forecast'!I7 -> -351.99945 | J31: =-'Shareholder''s Equity Forecast'!J7 -> -416.36436
B32: Cash Flow from Financing Activities | D32: =SUM(D27:D31) -> -575 | E32: =SUM(E27:E31) -> -714 | F32: =SUM(F27:F31) -> -559.32946 | G32: =SUM(G27:G31) -> -591.40453 | H32: =SUM(H27:H31) -> -562.64982 | I32: =SUM(I27:I31) -> -501.99945 | J32: =SUM(J27:J31) -> -566.36436
B34: Net Change in Cash | D34: =D32+D24+D17 -> 58.108342 | E34: =E32+E24+E17 -> -36.895075 | F34: =F32+F24+F17 -> -18.713267 | G34: =G32+G24+G17 -> -31.32094 | H34: =H32+H24+H17 -> 120.85192 | I34: =I32+I24+I17 -> 324.32827 | J34: =J32+J24+J17 -> 425.66635
B35: Beginning Cash Balance | D35: =C36 -> 27.5 | E35: =D36 -> 85.608342 | F35: =E36 -> 48.713267 | G35: =F36 -> 30 | H35: =G36 -> -1.3209401 | I35: =H36 -> 119.53098 | J35: =I36 -> 443.85925
B36: Ending Cash Balance | C36: ='Balance Sheet'!C7 -> 27.5 | D36: =SUM(D34:D35) -> 85.608342 | E36: =SUM(E34:E35) -> 48.713267 | F36: =SUM(F34:F35) -> 30 | G36: =SUM(G34:G35) -> -1.3209401 | H36: =SUM(H34:H35) -> 119.53098 | I36: =SUM(I34:I35) -> 443.85925 | J36: =SUM(J34:J35) -> 869.5256
B38: Check

Sheet Revenue and Cost Forecast
A1: Big Books Company
B2: Revenue and Cost Forecast
C3: Actuals | F3: Forecast
B4: ($ in Million Except Per Share Amounts) | C4: Historical 1 | D4: Historical 2 | E4: Historical 3 | F4: Forecast 1 | G4: Forecast 2 | H4: Forecast 3 | I4: Forecast 4 | J4: Forecast 5
B6: Segment 1 - Notebook
B7: Notebook (Million Units) | C7: 340 | D7: 391 | E7: =D7*(1+15%) -> 449.65 | F7: =E7*(1+F8) -> 472.1325 | G7: =F7*(1+G8) -> 542.95237 | H7: =G7*(1+H8) -> 624.39523 | I7: =H7*(1+I8) -> 718.05452 | J7: =I7*(1+J8) -> 825.76269
B8: % Growth | D8: =D7/C7-1 -> 0.15 | E8: =E7/D7-1 -> 0.15 | F8: 0.05 | G8: 0.15 | H8: 0.15 | I8: 0.15 | J8: 0.15
B10: Notebook (Price per unit) | C10: 5 | D10: 5.2 | E10: 5.3 | F10: =E10*(1+F11) -> 5.3 | G10: =F10*(1+G11) -> 5.406 | H10: =G10*(1+H11) -> 5.51412 | I10: =H10*(1+I11) -> 5.6244024 | J10: =I10*(1+J11) -> 5.7368904
B11: % Growth | F11: 0 | G11: 0.02 | H11: 0.02 | I11: 0.02 | J11: 0.02
B13: Revenue Notebook ($ Million) | C13: =C7*C10 -> 1700 | D13: =D7*D10 -> 2033.2 | E13: =E7*E10 -> 2383.145 | F13: =F7*F10 -> 2502.3023 | G13: =G7*G10 -> 2935.2005 | H13: =H7*H10 -> 3442.9902 | I13: =I7*I10 -> 4038.6275 | J13: =J7*J10 -> 4737.3101 | K13: =C13/$C$34 -> 0.58521002
K14: =C14/$C$34 -> 0
B15: Segment 2 - Writing Pads | K15: =C15/$C$34 -> 0
B16: Writing Pads (Million Units) | C16: 221.5838 | D16: 234.87883 | E16: 246.62277 | F16: =E16*(1+F17) -> 251.55522 | G16: =F16*(1+G17) -> 266.64854 | H16: =G16*(1+H17) -> 282.64745 | I16: =H16*(1+I17) -> 299.6063 | J16: =I16*(1+J17) -> 317.58268 | K16: =C16/$C$34 -> 0.076278271
B17: % Growth | D17: =D16/C16-1 -> 0.06 | E17: =E16/D16-1 -> 0.05 | F17: 0.02 | G17: 0.06 | H17: 0.06 | I17: 0.06 | J17: 0.06 | K17: =C17/$C$34 -> 0
K18: =C18/$C$34 -> 0
B19: Writing Pads (Price per unit) | C19: 2 | D19: 2.1 | E19: 2.2 | F19: =E19*(1+F20) -> 2.2 | G19: =F19*(1+G20) -> 2.31 | H19: =G19*(1+H20) -> 2.4255 | I19: =H19*(1+I20) -> 2.546775 | J19: =I19*(1+J20) -> 2.6741138 | K19: =C19/$C$34 -> 0.00068848238
B20: % Growth | D20: =D19/C19-1 -> 0.05 | E20: =E19/D19-1 -> 0.047619048 | F20: 0 | G20: 0.05 | H20: 0.05 | I20: 0.05 | J20: 0.05 | K20: =C20/$C$34 -> 0
K21: =C21/$C$34 -> 0
B22: Writing Pads ($ Million) | C22: =C16*C19 -> 443.1676 | D22: =D16*D19 -> 493.24554 | E22: =E16*E19 -> 542.57009 | F22: =F16*F19 -> 553.42149 | G22: =G16*G19 -> 615.95812 | H22: =H16*H19 -> 685.56139 | I22: =I16*I19 -> 763.02983 | J22: =J16*J19 -> 849.2522 | K22: =C22/$C$34 -> 0.15255654
K23: =C23/$C$34 -> 0
K24: =C24/$C$34 -> 0
B25: Segment 3 - Premium Journals | K25: =C25/$C$34 -> 0
B26: Premium Journal (Million Units) | C26: 76.17724 | D26: 80.141315 | E26: 86.103742 | F26: =E26*(1+F27) -> 88.686854 | G26: =F26*(1+G27) -> 94.894934 | H26: =G26*(1+H27) -> 101.53758 | I26: =H26*(1+I27) -> 108.64521 | J26: =I26*(1+J27) -> 116.25037 | K26: =C26/$C$34 -> 0.026223344
B27: % Growth | F27: 0.03 | G27: 0.07 | H27: 0.07 | I27: 0.07 | J27: 0.07 | K27: =C27/$C$34 -> 0
K28: =C28/$C$34 -> 0
B29: Premium Journal (Pricer per unit) | C29: 10 | D29: 11 | E29: 12 | F29: =E29*(1+F30) -> 12 | G29: =F29*(1+G30) -> 13.2 | H29: =G29*(1+H30) -> 14.52 | I29: =H29*(1+I30) -> 15.972 | J29: =I29*(1+J30) -> 17.5692 | K29: =C29/$C$34 -> 0.0034424119
B30: % Growth | F30: 0 | G30: 0.1 | H30: 0.1 | I30: 0.1 | J30: 0.1 | K30: =C30/$C$34 -> 0
K31: =C31/$C$34 -> 0
B32: Premium Journal ($ Million) | C32: =C26*C29 -> 761.7724 | D32: =D26*D29 -> 881.55447 | E32: =E26*E29 -> 1033.2449 | F32: =F26*F29 -> 1064.2423 | G32: =G26*G29 -> 1252.6131 | H32: =H26*H29 -> 1474.3257 | I32: =I26*I29 -> 1735.2813 | J32: =J26*J29 -> 2042.4261 | K32: =C32/$C$34 -> 0.26223344
B34: Total Revenue ($ Million) | C34: =C32+C22+C13 -> 2904.94 | D34: =D32+D22+D13 -> 3408 | E34: =E32+E22+E13 -> 3958.96 | F34: =F32+F22+F13 -> 4119.966 | G34: =G32+G22+G13 -> 4803.7718 | H34: =H32+H22+H13 -> 5602.8773 | I34: =I32+I22+I13 -> 6536.9387 | J34: =J32+J22+J13 -> 7628.9884
B39: Cost of Sales Forecast
B40: COGS
B41: Notebook | C41: 799 | D41: 975.936 | E41: 1239.2354 | F41: =F13*F42 -> 1376.2662 | G41: =G13*G42 -> 1614.3603 | H41: =H13*H42 -> 1893.6446 | I41: =I13*I42 -> 2221.2451 | J41: =J13*J42 -> 2605.5206
B42: Segmental Gross Margin (%) | C42: =C41/C13 -> 0.47 | D42: =D41/D13 -> 0.48 | E42: =E41/E13 -> 0.52 | F42: 0.55 | G42: 0.55 | H42: 0.55 | I42: 0.55 | J42: 0.55
B44: Writing Pads | C44: 257.03721 | D44: 295.94732 | E44: 339.10631 | F44: =F22*F45 -> 359.72397 | G44: =G22*G45 -> 400.37278 | H44: =H22*H45 -> 445.6149 | I44: =I22*I45 -> 495.96939 | J44: =J22*J45 -> 552.01393
B45: Segmental Gross Margin (%) | C45: =C44/C22 -> 0.58 | D45: =D44/D22 -> 0.6 | E45: =E44/E22 -> 0.625 | F45: 0.65 | G45: 0.65 | H45: 0.65 | I45: 0.65 | J45: 0.65
B47: Premium Journals | C47: 438.79942 | D47: 594.24128 | E47: 731.38547 | F47: =F32*F48 -> 766.25442 | G47: =G32*G48 -> 901.88145 | H47: =H32*H48 -> 1061.5145 | I47: =I32*I48 -> 1249.4025 | J47: =J32*J48 -> 1470.5468
B48: Segmental Gross Margin (%) | C48: =C47/C32 -> 0.57602431 | D48: =D47/D32 -> 0.67408346 | E48: =E47/E32 -> 0.70785296 | F48: 0.72 | G48: 0.72 | H48: 0.72 | I48: 0.72 | J48: 0.72
B50: Total Cost of Sales | C50: =C47+C44+C41 -> 1494.8366 | D50: =D47+D44+D41 -> 1866.1246 | E50: =E47+E44+E41 -> 2309.7272 | F50: =F47+F44+F41 -> 2502.2446 | G50: =G47+G44+G41 -> 2916.6145 | H50: =H47+H44+H41 -> 3400.774 | I50: =I47+I44+I41 -> 3966.6171 | J50: =J47+J44+J41 -> 4628.0813
C51: 1494.8366 | D51: 1866.1246 | E51: 2309.7272
...

Sheet Depreciation Capex Forecast
A1: Big Books Company
B2: Depreciation Capex Forecast
C3: Actuals | F3: Forecast
B4: ($ in Million Except Per Share Amounts) | C4: Historical 1 | D4: Historical 2 | E4: Historical 3 | F4: Forecast 1 | G4: Forecast 2 | H4: Forecast 3 | I4: Forecast 4 | J4: Forecast 5
B6: Gross PPE
B7: Land | C7: ='Balance Sheet'!C16 -> 30 | D7: ='Balance Sheet'!D16 -> 30 | E7: ='Balance Sheet'!E16 -> 30 | F7: =E7+F15 -> 30 | G7: =F7+G15 -> 30 | H7: =G7+H15 -> 30 | I7: =H7+I15 -> 30 | J7: =I7+J15 -> 30
B8: Machinery and equipment | C8: ='Balance Sheet'!C17 -> 630 | D8: ='Balance Sheet'!D17 -> 700 | E8: ='Balance Sheet'!E17 -> 875 | F8: =E8+F16 -> 1080.9983 | G8: =F8+G16 -> 1321.1869 | H8: =G8+H16 -> 1601.3308 | I8: =H8+I16 -> 1928.1777 | J8: =I8+J16 -> 2309.6271
B9: Automobiles and trucks | C9: ='Balance Sheet'!C18 -> 250 | D9: ='Balance Sheet'!D18 -> 325 | E9: ='Balance Sheet'!E18 -> 400 | F9: =E9+F17 -> 482.39932 | G9: =F9+G17 -> 578.47476 | H9: =G9+H17 -> 690.5323 | I9: =H9+I17 -> 821.27107 | J9: =I9+J17 -> 973.85084
B10: Total | C10: =SUM(C7:C9) -> 910 | D10: =SUM(D7:D9) -> 1055 | E10: =SUM(E7:E9) -> 1305 | F10: =SUM(F7:F9) -> 1593.3976 | G10: =SUM(G7:G9) -> 1929.6616 | H10: =SUM(H7:H9) -> 2321.8631 | I10: =SUM(I7:I9) -> 2779.4488 | J10: =SUM(J7:J9) -> 3313.4779
B12: Net Sales | C12: ='Income Statement'!C5 -> 2904.94 | D12: ='Income Statement'!D5 -> 3408 | E12: ='Income Statement'!E5 -> 3958.96 | F12: ='Income Statement'!F5 -> 4119.966 | G12: ='Income Statement'!G5 -> 4803.7718 | H12: ='Income Statement'!H5 -> 5602.8773 | I12: ='Income Statement'!I5 -> 6536.9387 | J12: ='Income Statement'!J5 -> 7628.9884
B14: Capital Expenditure by Segment
B15: Land | D15: =D7-C7 -> 0 | E15: =E7-D7 -> 0 | F15: =F12*F21 -> 0 | G15: =G12*G21 -> 0 | H15: =H12*H21 -> 0 | I15: =I12*I21 -> 0 | J15: =J12*J21 -> 0
B16: Machinery and equipment | D16: =D8-C8 -> 70 | E16: =E8-D8 -> 175 | F16: =F12*F22 -> 205.9983 | G16: =G12*G22 -> 240.18859 | H16: =H12*H22 -> 280.14386 | I16: =I12*I22 -> 326.84693 | J16: =J12*J22 -> 381.44942
B17: Automobiles and trucks | D17: =D9-C9 -> 75 | E17: =E9-D9 -> 75 | F17: =F12*F23 -> 82.39932 | G17: =G12*G23 -> 96.075436 | H17: =H12*H23 -> 112.05755 | I17: =I12*I23 -> 130.73877 | J17: =J12*J23 -> 152.57977
B18: Total | D18: =SUM(D15:D17) -> 145 | E18: =SUM(E15:E17) -> 250 | F18: =SUM(F15:F17) -> 288.39762 | G18: =SUM(G15:G17) -> 336.26403 | H18: =SUM(H15:H17) -> 392.20141 | I18: =SUM(I15:I17) -> 457.58571 | J18: =SUM(J15:J17) -> 534.02919
B20: Capital Expenditure as % Net Sales (By Segment)
B21: Land | D21: =D15/$D$12 -> 0 | E21: =E15/$E$12 -> 0 | F21: 0 | G21: 0 | H21: 0 | I21: 0 | J21: 0
B22: Machinery and equipment | D22: =D16/$D$12 -> 0.020539906 | E22: =E16/$E$12 -> 0.044203528 | F22: 0.05 | G22: 0.05 | H22: 0.05 | I22: 0.05 | J22: 0.05
B23: Automobiles and trucks | D23: =D17/$D$12 -> 0.022007042 | E23: =E17/$E$12 -> 0.018944369 | F23: 0.02 | G23: 0.02 | H23: 0.02 | I23: 0.02 | J23: 0.02
B24: Gross PPE
B26: Calculating Depreciation
B28: Machinery & Equipments
B29: Useful Life | C29: 10 | D29: Years | F29: 1 | G29: 2 | H29: 3 | I29: 4 | J29: 5
B30: Machinery & Equipments | C30: =E8 -> 875 | D30: last year machineary | F30: =$C30/$C29 -> 87.5 | G30: =$C30/$C29 -> 87.5 | H30: =$C30/$C29 -> 87.5 | I30: =$C30/$C29 -> 87.5 | J30: =$C30/$C29 -> 87.5
B31: Depreciation Expense (existing)
C33: Capex | D33: Useful Life
B34: Forecast 1 | C34: {=TRANSPOSE(F16:J16)} -> 205.9983 | D34: 12 | E34: Years | F34: =$C34/$D34 -> 17.166525 | G34: =$C34/$D34 -> 17.166525 | H34: =$C34/$D34 -> 17.166525 | I34: =$C34/$D34 -> 17.166525 | J34: =$C34/$D34 -> 17.166525
B35: Forecast 2 | C35: 240.18859 | D35: 12 | G35: =$C35/$D35 -> 20.015716 | H35: =$C35/$D35 -> 20.015716 | I35: =$C35/$D35 -> 20.015716 | J35: =$C35/$D35 -> 20.015716
B36: Forecast 3 | C36: 280.14386 | D36: 12 | H36: =$C36/$D36 -> 23.345322 | I36: =$C36/$D36 -> 23.345322 | J36: =$C36/$D36 -> 23.345322
B37: Forecast 4 | C37: 326.84693 | D37: 12 | I37: =$C37/$D37 -> 27.237244 | J37: =$C37/$D37 -> 27.237244
B38: Forecast 5 | C38: 381.44942 | D38: 12 | J38: =$C38/$D38 -> 31.787452
B40: Total Depreciation (Machinery & Equipments) | F40: =SUM(F30:F39) -> 104.66652 | G40: =SUM(G30:G39) -> 124.68224 | H40: =SUM(H30:H39) -> 148.02756 | I40: =SUM(I30:I39) -> 175.26481 | J40: =SUM(J30:J39) -> 207.05226
B42: Automobiles & Trucks
B43: Useful Life | C43: 10 | D43: Years | F43: 1 | G43: 2 | H43: 3 | I43: 4 | J43: 5
B44: Automobiles & Trucks | C44: =E9 -> 400 | D44: last year auto and transport | F44: =$C44/$C43 -> 40 | G44: =$C44/$C43 -> 40 | H44: =$C44/$C43 -> 40 | I44: =$C44/$C43 -> 40 | J44: =$C44/$C43 -> 40
B45: Depreciation Expense (existing)
C47: Capex | D47: Useful Life
B48: Forecast 1 | C48: {=TRANSPOSE(F17:J17)} -> 82.39932 | D48: 12 | F48: =$C48/$D48 -> 6.86661 | G48: =$C48/$D48 -> 6.86661 | H48: =$C48/$D48 -> 6.86661 | I48: =$C48/$D48 -> 6.86661 | J48: =$C48/$D48 -> 6.86661
B49: Forecast 2 | C49: 96.075436 | D49: 12 | G49: =$C49/$D49 -> 8.0062863 | H49: =$C49/$D49 -> 8.0062863 | I49: =$C49/$D49 -> 8.0062863 | J49: =$C49/$D49 -> 8.0062863
B50: Forecast 3 | C50: 112.05755 | D50: 12 | H50: =$C50/$D50 -> 9.3381288 | I50: =$C50/$D50 -> 9.3381288 | J50: =$C50/$D50 -> 9.3381288
...

Sheet Working Capital Forecast
A1: Big Books Company
B2: Working Capital Forecast
C3: Actuals | F3: Forecast
B4: ($ in Million Except Per Share Amounts) | C4: Historical 1 | D4: Historical 2 | E4: Historical 3 | F4: Forecast 1 | G4: Forecast 2 | H4: Forecast 3 | I4: Forecast 4 | J4: Forecast 5
B6: Working Capital Balances
B7: Receivable | C7: ='Balance Sheet'!C9 -> 462.9 | D7: ='Balance Sheet'!D9 -> 473.7 | E7: ='Balance Sheet'!E9 -> 473 | F7: =F$17/F21 -> 474.07828 | G7: =G$17/G21 -> 552.76278 | H7: =H$17/H21 -> 644.71465 | I7: =I$17/I21 -> 752.19568 | J7: =J$17/J21 -> 877.8562
B8: Inventory | C8: ='Balance Sheet'!C10 -> 327 | D8: ='Balance Sheet'!D10 -> 350.2 | E8: ='Balance Sheet'!E10 -> 383.8 | F8: =F$18/F22 -> 411.32788 | G8: =G$18/G22 -> 479.44348 | H8: =H$18/H22 -> 559.03134 | I8: =I$18/I22 -> 652.04664 | J8: =J$18/J22 -> 760.78048
B9: Other Current Assets | C9: ='Balance Sheet'!C11 -> 87.4 | D9: ='Balance Sheet'!D11 -> 82.8 | E9: ='Balance Sheet'!E11 -> 83.5 | F9: =F17*F30 -> 82.39932 | G9: =G17*G30 -> 96.075436 | H9: =H17*H30 -> 112.05755 | I9: =I17*I30 -> 130.73877 | J9: =J17*J30 -> 152.57977
B10: Total Non Cash Current Assets | C10: =SUM(C7:C9) -> 877.3 | D10: =SUM(D7:D9) -> 906.7 | E10: =SUM(E7:E9) -> 940.3 | F10: =SUM(F7:F9) -> 967.80548 | G10: =SUM(G7:G9) -> 1128.2817 | H10: =SUM(H7:H9) -> 1315.8035 | I10: =SUM(I7:I9) -> 1534.9811 | J10: =SUM(J7:J9) -> 1791.2164
B12: Accounts Payable | C12: ='Balance Sheet'!C30 -> 206.4 | D12: ='Balance Sheet'!D30 -> 221.4 | E12: ='Balance Sheet'!E30 -> 279.1 | F12: =F$18/F23 -> 308.49591 | G12: =G$18/G23 -> 359.58261 | H12: =H$18/H23 -> 419.27351 | I12: =I$18/I23 -> 489.03498 | J12: =J$18/J23 -> 570.58536
B13: Accrued Liabilities | C13: ='Balance Sheet'!C31 -> 180.7 | D13: ='Balance Sheet'!D31 -> 161.3 | E13: ='Balance Sheet'!E31 -> 176.7 | F13: =F18*F31 -> 200.17957 | G13: =G18*G31 -> 233.32916 | H13: =H18*H31 -> 272.06192 | I13: =I18*I31 -> 317.32937 | J13: =J18*J31 -> 370.2465
B14: Other Current Liabilities | C14: ='Balance Sheet'!C32 -> 68.3 | D14: ='Balance Sheet'!D32 -> 62.8 | E14: ='Balance Sheet'!E32 -> 81.8 | F14: =F18*F32 -> 87.578562 | G14: =G18*G32 -> 102.08151 | H14: =H18*H32 -> 119.02709 | I14: =I18*I32 -> 138.8316 | J14: =J18*J32 -> 161.98284
B15: Total Non-Debt Current Liabilities | C15: =SUM(C12:C14) -> 455.4 | D15: =SUM(D12:D14) -> 445.5 | E15: =SUM(E12:E14) -> 537.6 | F15: =SUM(F12:F14) -> 596.25405 | G15: =SUM(G12:G14) -> 694.99328 | H15: =SUM(H12:H14) -> 810.36252 | I15: =SUM(I12:I14) -> 945.19594 | J15: =SUM(J12:J14) -> 1102.8147
B17: Net Sales | C17: ='Income Statement'!C5 -> 2904.94 | D17: ='Income Statement'!D5 -> 3408 | E17: ='Income Statement'!E5 -> 3958.96 | F17: ='Income Statement'!F5 -> 4119.966 | G17: ='Income Statement'!G5 -> 4803.7718 | H17: ='Income Statement'!H5 -> 5602.8773 | I17: ='Income Statement'!I5 -> 6536.9387 | J17: ='Income Statement'!J5 -> 7628.9884 | L17: Number of days assumption | M17: 365
B18: Cost of Sales | C18: ='Income Statement'!C6 -> 1494.8366 | D18: ='Income Statement'!D6 -> 1866.1246 | E18: ='Income Statement'!E6 -> 2309.7272 | F18: ='Income Statement'!F6 -> 2502.2446 | G18: ='Income Statement'!G6 -> 2916.6145 | H18: ='Income Statement'!H6 -> 3400.774 | I18: ='Income Statement'!I6 -> 3966.6171 | J18: ='Income Statement'!J6 -> 4628.0813
B20: Turnover Ratios
B21: Receivables turnover (Net Sales / Receivables) | C21: =C17/C7 -> 6.2755239 | D21: =D17/D7 -> 7.1944269 | E21: =E17/E7 -> 8.3698943 | F21: =$M$17/F25 -> 8.6904762 | G21: =$M$17/G25 -> 8.6904762 | H21: =$M$17/H25 -> 8.6904762 | I21: =$M$17/I25 -> 8.6904762 | J21: =$M$17/J25 -> 8.6904762
B22: Inventory turnover (Cost of Sales / Inventory) | C22: =C18/C8 -> 4.5713658 | D22: =D18/D8 -> 5.3287396 | E22: =E18/E8 -> 6.0180489 | F22: =$M$17/F26 -> 6.0833333 | G22: =$M$17/G26 -> 6.0833333 | H22: =$M$17/H26 -> 6.0833333 | I22: =$M$17/I26 -> 6.0833333 | J22: =$M$17/J26 -> 6.0833333
B23: Accounts Payables turnover (Cost of Sales / Accounts Payable) | C23: =C18/C12 -> 7.2424255 | D23: =D18/D12 -> 8.4287471 | E23: =E18/E12 -> 8.2756258 | F23: =$M$17/F27 -> 8.1111111 | G23: =$M$17/G27 -> 8.1111111 | H23: =$M$17/H27 -> 8.1111111 | I23: =$M$17/I27 -> 8.1111111 | J23: =$M$17/J27 -> 8.1111111
B25: Receivables collection period (365 / Receivables Turnover) | C25: =$M$17/C21 -> 58.162475 | D25: =$M$17/D21 -> 50.733715 | E25: =$M$17/E21 -> 43.608675 | F25: 42 | G25: 42 | H25: 42 | I25: 42 | J25: 42
B26: Inventory processing period (365 / Inventory Turnover) | C26: =$M$17/C22 -> 79.844846 | D26: =$M$17/D22 -> 68.496498 | E26: =$M$17/E22 -> 60.650886 | F26: 60 | G26: 60 | H26: 60 | I26: 60 | J26: 60
B27: Payment period (365 / Accounts Payable Turnover) | C27: =$M$17/C23 -> 50.397481 | D27: =$M$17/D23 -> 43.304182 | E27: =$M$17/E23 -> 44.105426 | F27: 45 | G27: 45 | H27: 45 | I27: 45 | J27: 45
B28: Cash Collection Cycle | C28: =C26+C25-C27 -> 87.60984 | D28: =D26+D25-D27 -> 75.92603 | E28: =E26+E25-E27 -> 60.154136 | F28: =F26+F25-F27 -> 57 | G28: =G26+G25-G27 -> 57 | H28: =H26+H25-H27 -> 57 | I28: =I26+I25-I27 -> 57 | J28: =J26+J25-J27 -> 57
B30: Other Current Assets (% of Net Sales) | C30: =C9/C17 -> 0.03008668 | D30: =D9/D17 -> 0.024295775 | E30: =E9/E17 -> 0.021091398 | F30: 0.02 | G30: 0.02 | H30: 0.02 | I30: 0.02 | J30: 0.02
B31: Accrued Liabilities (% of Cost of Sales) | C31: =C13/C18 -> 0.12088278 | D31: =D13/D18 -> 0.086435814 | E31: =E13/E18 -> 0.076502542 | F31: 0.08 | G31: 0.08 | H31: 0.08 | I31: 0.08 | J31: 0.08
B32: Other Current Liabilities (% of Cost of Sales) | C32: =C14/C18 -> 0.045690612 | D32: =D14/D18 -> 0.03365263 | E32: =E14/E18 -> 0.035415438 | F32: 0.035 | G32: 0.035 | H32: 0.035 | I32: 0.035 | J32: 0.035
B34: Cash Flow from Individual line items
B35: Receivable | F35: =-(F7-E7) -> -1.078279 | G35: =-(G7-F7) -> -78.684503 | H35: =-(H7-G7) -> -91.951864 | I35: =-(I7-H7) -> -107.48104 | J35: =-(J7-I7) -> -125.66052
B36: Inventory | F36: =-(F8-E8) -> -27.527884 | G36: =-(G8-F8) -> -68.1156 | H36: =-(H8-G8) -> -79.587859 | I36: =-(I8-H8) -> -93.015299 | J36: =-(J8-I8) -> -108.73384
B37: Other Current Assets | F37: =-(F9-E9) -> 1.1006801 | G37: =-(G9-F9) -> -13.676116 | H37: =-(H9-G9) -> -15.98211 | I37: =-(I9-H9) -> -18.681228 | J37: =-(J9-I9) -> -21.840994
B38: Accounts Payable | F38: =F12-E12 -> 29.395913 | G38: =G12-F12 -> 51.0867 | H38: =H12-G12 -> 59.690894 | I38: =I12-H12 -> 69.761474 | J38: =J12-I12 -> 81.550381
B39: Accrued Liabilities | F39: =F13-E13 -> 23.47957 | G39: =G13-F13 -> 33.149592 | H39: =H13-G13 -> 38.732758 | I39: =I13-H13 -> 45.267445 | J39: =J13-I13 -> 52.917136
B40: Other Current Liabilities | F40: =F14-E14 -> 5.778562 | G40: =G14-F14 -> 14.502947 | H40: =H14-G14 -> 16.945582 | I40: =I14-H14 -> 19.804507 | J40: =J14-I14 -> 23.151247
B41: (Incease)/ Decrease in Working Capital | F41: =SUM(F35:F40) -> 31.148562 | G41: =SUM(G35:G40) -> -61.73698 | H41: =SUM(H35:H40) -> -72.152599 | I41: =SUM(I35:I40) -> -84.344136 | J41: =SUM(J35:J40) -> -98.616588

Sheet Amortization Forecast
A1: Big Books Company
B2: Amortization Forecast
C3: Actuals | F3: Forecast
B4: ($ in Million Except Per Share Amounts) | C4: Historical 1 | D4: Historical 2 | E4: Historical 3 | F4: Forecast 1 | G4: Forecast 2 | H4: Forecast 3 | I4: Forecast 4 | J4: Forecast 5
B6: Net Sales | C6: ='Income Statement'!C5 -> 2904.94 | D6: ='Income Statement'!D5 -> 3408 | E6: ='Income Statement'!E5 -> 3958.96 | F6: ='Income Statement'!F5 -> 4119.966 | G6: ='Income Statement'!G5 -> 4803.7718 | H6: ='Income Statement'!H5 -> 5602.8773 | I6: ='Income Statement'!I5 -> 6536.9387 | J6: ='Income Statement'!J5 -> 7628.9884
B7: Additions to Intangibles | D7: =-'Cash Flow Statement'!D23 -> 26.466 | E7: =-'Cash Flow Statement'!E23 -> 30.735 | F7: =F6*F8 -> 32.959728 | G7: =G6*G8 -> 38.430174 | H7: =H6*H8 -> 44.823018 | I7: =I6*I8 -> 52.295509 | J7: =J6*J8 -> 61.031907
B8: Additions to Intangibles as % of Net Sales | D8: =D7/D6 -> 0.0077658451 | E8: =E7/E6 -> 0.0077634025 | F8: 0.008 | G8: 0.008 | H8: 0.008 | I8: 0.008 | J8: 0.008
B10: Beginning Net Intangibles | D10: =C13 -> 46.5 | E10: =D13 -> 62.3 | F10: =E13 -> 80 | G10: =F13 -> 99.663755 | H10: =G13 -> 120.95494 | I10: =H13 -> 144.15667 | J10: =I13 -> 169.60133
B11: Additions to Intangibles | D11: =D7 -> 26.466 | E11: =E7 -> 30.735 | F11: =F7 -> 32.959728 | G11: =G7 -> 38.430174 | H11: =H7 -> 44.823018 | I11: =I7 -> 52.295509 | J11: =J7 -> 61.031907
B12: (Amortization Expense) | D12: ='Income Statement'!D13 -> 10.666 | E12: ='Income Statement'!E13 -> 13.035 | F12: =F28 -> 13.295973 | G12: =G28 -> 17.13899 | H12: =H28 -> 21.621292 | I12: =I28 -> 26.850843 | J12: =J28 -> 32.954034
B13: Ending Net Intangibles | C13: ='Balance Sheet'!C24 -> 46.5 | D13: =D10+D11-D12 -> 62.3 | E13: =E10+E11-E12 -> 80 | F13: =F10+F11-F12 -> 99.663755 | G13: =G10+G11-G12 -> 120.95494 | H13: =H10+H11-H12 -> 144.15667 | I13: =I10+I11-I12 -> 169.60133 | J13: =J10+J11-J12 -> 197.67921
E15: From:
E16: Existing Intangibles
